package errors

import (
	stdErrors "errors"

	"github.com/onflow/cadence/runtime"
	"github.com/onflow/cadence/runtime/interpreter"
)

// Error covers all non-fatal errors happing
// while validating and executing a transaction or an script.
type Error interface {
	// Code returns the code for this error
	Code() uint32
	// and anything else that is needed to be an error
	error
}

// Failure captures fatal unexpected virtual machine errors,
// we capture this type of error instead of panicing
// to collect all necessary data before crashing
// if any of these errors occurs we should halt the
// execution.
type Failure interface {
	FailureCode() uint16
	error
}

// Is provides error.As utility functionality,
// it does look into nested errors by callin `unwrap`
// method on source and calls `is` method on each level.
// if no is method is provided it does equality comparison.
func Is(source, target error) bool {
	return stdErrors.Is(source, target)
}

// As is a utility function similar to Is but can be
// also used for interfaces and also writes the found error with the type
// into the target
func As(err error, target interface{}) bool {
	return stdErrors.As(err, target)
}

// SplitErrorTypes splits the error into fatal (failures) and non-fatal errors
func SplitErrorTypes(inp error) (err Error, failure Failure) {
	// failures should get the priority
	// this method will check all the levels for these failures
	if As(inp, &failure) {
		return nil, failure
	}
	// then we should try to match known non-fatal errors
	if As(inp, &err) {
		return err, nil
	}
	// anything else that is left is an unknown failure
	// (except the ones green listed for now to be considered as txErrors)
	if err != nil {
		return nil, &UnknownFailure{Err: err}
	}
	return nil, nil
}

// HandleRuntimeError handles runtime errors and separates
// errors generated by runtime from fvm errors (e.g. environment errors)
func HandleRuntimeError(err error) error {
	var runErr runtime.Error
	var ok bool
	// if is not a runtime error return as vm error
	// this should never happen unless a bug in the code
	if runErr, ok = err.(runtime.Error); !ok {
		return &UnknownFailure{runErr}
	}
	innerErr := runErr.Err

	// External errors are reported by the runtime but originate from the VM.
	// External errors may be fatal or non-fatal, so additional handling by SplitErrorTypes
	if externalErr, ok := innerErr.(interpreter.ExternalError); ok {
		if recoveredErr, ok := externalErr.Recovered.(error); ok {
			// If the recovered value is an error, pass it to the original
			// error handler to distinguish between fatal and non-fatal errors.
			return recoveredErr
		}
		// if not recovered return
		return &UnknownFailure{externalErr}
	}

	// All other errors are non-fatal Cadence errors.
	return &CadenceRuntimeError{Err: &runErr}
}
